{
  "test_error_recovery.py": {
    "methods_found": 13,
    "passed": 11,
    "failed": 6,
    "skipped": 0,
    "errors": 0,
    "duration": 1.001833200454712,
    "return_code": 1,
    "stdout": "============================= test session starts ==============================\nplatform linux -- Python 3.12.3, pytest-8.4.2, pluggy-1.6.0 -- /usr/bin/python\ncachedir: .pytest_cache\nbenchmark: 5.1.0 (defaults: timer=time.perf_counter disable_gc=False min_rounds=5 min_time=0.000005 max_time=1.0 calibration_precision=10 warmup=False warmup_iterations=100000)\nrootdir: /home/nando/projects/Claude-subagents/tests\nconfigfile: pytest.ini\nplugins: benchmark-5.1.0, asyncio-1.1.0, cov-6.2.1\nasyncio: mode=Mode.AUTO, asyncio_default_fixture_loop_scope=None, asyncio_default_test_loop_scope=function\ncollecting ... collected 17 items\n\ntests/test_error_recovery.py::TestFileSystemFailures::test_disk_full_handling PASSED [  5%]\ntests/test_error_recovery.py::TestFileSystemFailures::test_permission_denied_recovery PASSED [ 11%]\ntests/test_error_recovery.py::TestFileSystemFailures::test_corrupted_file_handling PASSED [ 17%]\ntests/test_error_recovery.py::TestFileSystemFailures::test_directory_not_writable PASSED [ 23%]\ntests/test_error_recovery.py::TestFileSystemFailures::test_file_lock_handling FAILED [ 29%]\ntests/test_error_recovery.py::TestNetworkFailures::test_connection_timeout FAILED [ 35%]\ntests/test_error_recovery.py::TestNetworkFailures::test_connection_refused FAILED [ 41%]\ntests/test_error_recovery.py::TestNetworkFailures::test_http_error_codes FAILED [ 47%]\ntests/test_error_recovery.py::TestNetworkFailures::test_dns_resolution_failure FAILED [ 52%]\ntests/test_error_recovery.py::TestProcessCrashes::test_subprocess_crash_recovery PASSED [ 58%]\ntests/test_error_recovery.py::TestProcessCrashes::test_main_process_recovery PASSED [ 64%]\ntests/test_error_recovery.py::TestProcessCrashes::test_cleanup_after_crash FAILED [ 70%]\ntests/test_error_recovery.py::TestProcessCrashes::test_restart_logic PASSED [ 76%]\ntests/test_error_recovery.py::TestDataCorruption::test_corrupted_token_store PASSED [ 82%]\ntests/test_error_recovery.py::TestDataCorruption::test_corrupted_cache PASSED [ 88%]\ntests/test_error_recovery.py::TestDataCorruption::test_checksum_validation PASSED [ 94%]\ntests/test_error_recovery.py::TestDataCorruption::test_backup_restore_mechanism PASSED [100%]\n\n=================================== FAILURES ===================================\n________________ TestFileSystemFailures.test_file_lock_handling ________________\ntests/test_error_recovery.py:176: in test_file_lock_handling\n    assert retry_count == max_retries\nE   assert 0 == 3\n_________________ TestNetworkFailures.test_connection_timeout __________________\ntests/test_error_recovery.py:189: in test_connection_timeout\n    import aiohttp\nE   ModuleNotFoundError: No module named 'aiohttp'\n_________________ TestNetworkFailures.test_connection_refused __________________\ntests/test_error_recovery.py:215: in test_connection_refused\n    import aiohttp\nE   ModuleNotFoundError: No module named 'aiohttp'\n__________________ TestNetworkFailures.test_http_error_codes ___________________\ntests/test_error_recovery.py:273: in test_http_error_codes\n    import aiohttp\nE   ModuleNotFoundError: No module named 'aiohttp'\n_______________ TestNetworkFailures.test_dns_resolution_failure ________________\ntests/test_error_recovery.py:303: in test_dns_resolution_failure\n    import aiohttp\nE   ModuleNotFoundError: No module named 'aiohttp'\n_________________ TestProcessCrashes.test_cleanup_after_crash __________________\ntests/test_error_recovery.py:470: in test_cleanup_after_crash\n    assert cleanup_success is True\nE   assert False is True\n=========================== short test summary info ============================\nFAILED tests/test_error_recovery.py::TestFileSystemFailures::test_file_lock_handling\nFAILED tests/test_error_recovery.py::TestNetworkFailures::test_connection_timeout\nFAILED tests/test_error_recovery.py::TestNetworkFailures::test_connection_refused\nFAILED tests/test_error_recovery.py::TestNetworkFailures::test_http_error_codes\nFAILED tests/test_error_recovery.py::TestNetworkFailures::test_dns_resolution_failure\nFAILED tests/test_error_recovery.py::TestProcessCrashes::test_cleanup_after_crash\n=================== 6 failed, 11 passed, 8 warnings in 0.57s ===================\n",
    "stderr": ""
  },
  "test_edge_cases.py": {
    "methods_found": 12,
    "passed": 15,
    "failed": 1,
    "skipped": 0,
    "errors": 0,
    "duration": 2.7289562225341797,
    "return_code": 1,
    "stdout": "============================= test session starts ==============================\nplatform linux -- Python 3.12.3, pytest-8.4.2, pluggy-1.6.0 -- /usr/bin/python\ncachedir: .pytest_cache\nbenchmark: 5.1.0 (defaults: timer=time.perf_counter disable_gc=False min_rounds=5 min_time=0.000005 max_time=1.0 calibration_precision=10 warmup=False warmup_iterations=100000)\nrootdir: /home/nando/projects/Claude-subagents/tests\nconfigfile: pytest.ini\nplugins: benchmark-5.1.0, asyncio-1.1.0, cov-6.2.1\nasyncio: mode=Mode.AUTO, asyncio_default_fixture_loop_scope=None, asyncio_default_test_loop_scope=function\ncollecting ... collected 16 items\n\ntests/test_edge_cases.py::TestInputEdgeCases::test_empty_inputs PASSED   [  6%]\ntests/test_edge_cases.py::TestInputEdgeCases::test_extremely_large_inputs PASSED [ 12%]\ntests/test_edge_cases.py::TestInputEdgeCases::test_special_characters PASSED [ 18%]\ntests/test_edge_cases.py::TestInputEdgeCases::test_boundary_values PASSED [ 25%]\ntests/test_edge_cases.py::TestInputEdgeCases::test_encoding_edge_cases PASSED [ 31%]\ntests/test_edge_cases.py::TestConcurrencyEdgeCases::test_concurrent_modifications PASSED [ 37%]\ntests/test_edge_cases.py::TestConcurrencyEdgeCases::test_race_conditions PASSED [ 43%]\ntests/test_edge_cases.py::TestConcurrencyEdgeCases::test_deadlock_prevention FAILED [ 50%]\ntests/test_edge_cases.py::TestConcurrencyEdgeCases::test_thread_pool_exhaustion PASSED [ 56%]\ntests/test_edge_cases.py::TestResourceExhaustion::test_memory_exhaustion_simulation PASSED [ 62%]\ntests/test_edge_cases.py::TestResourceExhaustion::test_file_descriptor_exhaustion_simulation PASSED [ 68%]\ntests/test_edge_cases.py::TestResourceExhaustion::test_disk_space_exhaustion_simulation PASSED [ 75%]\ntests/test_edge_cases.py::TestResourceExhaustion::test_cpu_exhaustion_simulation PASSED [ 81%]\ntests/test_edge_cases.py::TestAsyncEdgeCases::test_asyncio_timeout_handling PASSED [ 87%]\ntests/test_edge_cases.py::TestAsyncEdgeCases::test_async_exception_propagation PASSED [ 93%]\ntests/test_edge_cases.py::TestAsyncEdgeCases::test_async_resource_cleanup PASSED [100%]\n\n=================================== FAILURES ===================================\n______________ TestConcurrencyEdgeCases.test_deadlock_prevention _______________\ntests/test_edge_cases.py:491: in test_deadlock_prevention\n    assert isinstance(result, str)  # Should return string result\n    ^^^^^^^^^^^^^^^^^^^^^^^^^^^^^^\nE   assert False\nE    +  where False = isinstance(TypeError(\"'coroutine' object does not support the asynchronous context manager protocol\"), str)\n=========================== short test summary info ============================\nFAILED tests/test_edge_cases.py::TestConcurrencyEdgeCases::test_deadlock_prevention\n================== 1 failed, 15 passed, 10 warnings in 2.28s ===================\n",
    "stderr": ""
  },
  "test_failover.py": {
    "methods_found": 4,
    "passed": 11,
    "failed": 2,
    "skipped": 0,
    "errors": 0,
    "duration": 1.782167673110962,
    "return_code": 1,
    "stdout": "============================= test session starts ==============================\nplatform linux -- Python 3.12.3, pytest-8.4.2, pluggy-1.6.0 -- /usr/bin/python\ncachedir: .pytest_cache\nbenchmark: 5.1.0 (defaults: timer=time.perf_counter disable_gc=False min_rounds=5 min_time=0.000005 max_time=1.0 calibration_precision=10 warmup=False warmup_iterations=100000)\nrootdir: /home/nando/projects/Claude-subagents/tests\nconfigfile: pytest.ini\nplugins: benchmark-5.1.0, asyncio-1.1.0, cov-6.2.1\nasyncio: mode=Mode.AUTO, asyncio_default_fixture_loop_scope=None, asyncio_default_test_loop_scope=function\ncollecting ... collected 13 items\n\ntests/test_failover.py::TestGracefulDegradation::test_degraded_mode_activation FAILED [  7%]\ntests/test_failover.py::TestGracefulDegradation::test_feature_toggling PASSED [ 15%]\ntests/test_failover.py::TestCircuitBreaker::test_circuit_breaker_open PASSED [ 23%]\ntests/test_failover.py::TestCircuitBreaker::test_circuit_breaker_recovery PASSED [ 30%]\ntests/test_failover.py::TestCircuitBreaker::test_circuit_breaker_timeout_handling PASSED [ 38%]\ntests/test_failover.py::TestCircuitBreaker::test_circuit_breaker_metrics PASSED [ 46%]\ntests/test_failover.py::TestRetryMechanisms::test_exponential_backoff PASSED [ 53%]\ntests/test_failover.py::TestRetryMechanisms::test_retry_with_jitter PASSED [ 61%]\ntests/test_failover.py::TestRetryMechanisms::test_retry_max_attempts PASSED [ 69%]\ntests/test_failover.py::TestRetryMechanisms::test_retry_immediate_success PASSED [ 76%]\ntests/test_failover.py::TestServiceDiscovery::test_service_registration_and_discovery PASSED [ 84%]\ntests/test_failover.py::TestServiceDiscovery::test_load_balancing_with_failover FAILED [ 92%]\ntests/test_failover.py::TestServiceDiscovery::test_health_check_recovery PASSED [100%]\n\n=================================== FAILURES ===================================\n____________ TestGracefulDegradation.test_degraded_mode_activation _____________\ntests/test_failover.py:283: in test_degraded_mode_activation\n    assert system.available_features[\"auto_optimization\"] is False\n           ^^^^^^^^^^^^^^^^^^^^^^^^^^^^^^^^^^^^^^^^^^^^^^\nE   KeyError: 'auto_optimization'\n____________ TestServiceDiscovery.test_load_balancing_with_failover ____________\ntests/test_failover.py:681: in test_load_balancing_with_failover\n    assert \"http://service1.example.com\" not in healthy_endpoints\nE   AssertionError: assert 'http://service1.example.com' not in ['http://service1.example.com', 'http://service2.example.com', 'http://service3.example.com']\n=========================== short test summary info ============================\nFAILED tests/test_failover.py::TestGracefulDegradation::test_degraded_mode_activation\nFAILED tests/test_failover.py::TestServiceDiscovery::test_load_balancing_with_failover\n=================== 2 failed, 11 passed, 8 warnings in 1.36s ===================\n",
    "stderr": ""
  },
  "test_data_integrity.py": {
    "methods_found": 8,
    "passed": 6,
    "failed": 2,
    "skipped": 0,
    "errors": 0,
    "duration": 0.7179808616638184,
    "return_code": 1,
    "stdout": "============================= test session starts ==============================\nplatform linux -- Python 3.12.3, pytest-8.4.2, pluggy-1.6.0 -- /usr/bin/python\ncachedir: .pytest_cache\nbenchmark: 5.1.0 (defaults: timer=time.perf_counter disable_gc=False min_rounds=5 min_time=0.000005 max_time=1.0 calibration_precision=10 warmup=False warmup_iterations=100000)\nrootdir: /home/nando/projects/Claude-subagents/tests\nconfigfile: pytest.ini\nplugins: benchmark-5.1.0, asyncio-1.1.0, cov-6.2.1\nasyncio: mode=Mode.AUTO, asyncio_default_fixture_loop_scope=None, asyncio_default_test_loop_scope=function\ncollecting ... collected 8 items\n\ntests/test_data_integrity.py::TestTransactionRollback::test_partial_operation_rollback PASSED [ 12%]\ntests/test_data_integrity.py::TestTransactionRollback::test_multi_step_rollback PASSED [ 25%]\ntests/test_data_integrity.py::TestTransactionRollback::test_nested_transaction_rollback PASSED [ 37%]\ntests/test_data_integrity.py::TestDataValidation::test_checksum_verification FAILED [ 50%]\ntests/test_data_integrity.py::TestDataValidation::test_schema_validation PASSED [ 62%]\ntests/test_data_integrity.py::TestDataValidation::test_data_migration_validation PASSED [ 75%]\ntests/test_data_integrity.py::TestBackupRestore::test_automatic_backup PASSED [ 87%]\ntests/test_data_integrity.py::TestBackupRestore::test_restore_from_backup FAILED [100%]\n\n=================================== FAILURES ===================================\n________________ TestDataValidation.test_checksum_verification _________________\ntests/test_data_integrity.py:466: in test_checksum_verification\n    assert success is True\nE   assert False is True\n__________________ TestBackupRestore.test_restore_from_backup __________________\ntests/test_data_integrity.py:903: in test_restore_from_backup\n    backup_manager = BackupManager(self.data_dir, self.backup_dir)\n                     ^^^^^^^^^^^^^\nE   NameError: name 'BackupManager' is not defined\n=========================== short test summary info ============================\nFAILED tests/test_data_integrity.py::TestDataValidation::test_checksum_verification\nFAILED tests/test_data_integrity.py::TestBackupRestore::test_restore_from_backup\n=================== 2 failed, 6 passed, 8 warnings in 0.28s ====================\n",
    "stderr": ""
  }
}